Workbook

Sheet DASSBOARD
A1: 30 DAYS HABIT TRACKER
M2: actual | N2: =Sheet1!AG13 -> 0.25
M3: remaining | N3: =1-N2 -> 0.75
M4: total | N4: 1
AO10: TOP HABBIT | AQ10: TOTAL COMPLETE
AO11: =INDEX(Sheet4!A23:A32,MATCH(MAX(Sheet1!AG2:AG11),Sheet1!AG2:AG11,0)) -> Walking /Step | AQ11: =SUM(Sheet1!AF2:AF11) -> 75
AQ13: 30 DAYS
AQ14: 30
A25: COMPLETION RATE
A26: =SUM(Sheet1!AF2:AF11)/(10*30) -> 0.25
A30: 30 DAYS HABIT OVERVIEW | B30: DAY 1
A31: WAKE UP AT 5 : 30 | B31: =Sheet4!B23 -> 1 | C31: =Sheet4!C23 -> 1 | D31: =Sheet4!D23 -> 1 | E31: =Sheet4!E23 -> 1 | F31: =Sheet4!F23 -> 1 | G31: =Sheet4!G23 -> 1 | H31: =Sheet4!H23 -> 1 | I31: =Sheet4!I23 -> 0 | ... AE31: =Sheet4!AE23 -> 0
A32: GYM | B32: =Sheet4!B24 -> 0 | C32: =Sheet4!C24 -> 0 | D32: =Sheet4!D24 -> 0 | E32: =Sheet4!E24 -> 0 | F32: =Sheet4!F24 -> 0 | G32: =Sheet4!G24 -> 0 | H32: =Sheet4!H24 -> 0 | I32: =Sheet4!I24 -> 0 | ... AE32: =Sheet4!AE24 -> 0
A33: READING / LEARNING | B33: =Sheet4!B25 -> 0 | C33: =Sheet4!C25 -> 0 | D33: =Sheet4!D25 -> 0 | E33: =Sheet4!E25 -> 0 | F33: =Sheet4!F25 -> 0 | G33: =Sheet4!G25 -> 0 | H33: =Sheet4!H25 -> 0 | I33: =Sheet4!I25 -> 0 | ... AE33: =Sheet4!AE25 -> 0
A34: NOO GOONING | B34: =Sheet4!B26 -> 0 | C34: =Sheet4!C26 -> 0 | D34: =Sheet4!D26 -> 0 | E34: =Sheet4!E26 -> 0 | F34: =Sheet4!F26 -> 0 | G34: =Sheet4!G26 -> 0 | H34: =Sheet4!H26 -> 0 | I34: =Sheet4!I26 -> 0 | ... AE34: =Sheet4!AE26 -> 0
A35: DIET | B35: =Sheet4!B27 -> 0 | C35: =Sheet4!C27 -> 0 | D35: =Sheet4!D27 -> 0 | E35: =Sheet4!E27 -> 0 | F35: =Sheet4!F27 -> 0 | G35: =Sheet4!G27 -> 0 | H35: =Sheet4!H27 -> 0 | I35: =Sheet4!I27 -> 0 | ... AE35: =Sheet4!AE27 -> 0
A36: LEARNING SKILL | B36: =Sheet4!B28 -> 0 | C36: =Sheet4!C28 -> 0 | D36: =Sheet4!D28 -> 0 | E36: =Sheet4!E28 -> 0 | F36: =Sheet4!F28 -> 0 | G36: =Sheet4!G28 -> 1 | H36: =Sheet4!H28 -> 1 | I36: =Sheet4!I28 -> 1 | ... AE36: =Sheet4!AE28 -> 1
A37: CODING | B37: =Sheet4!B29 -> 0 | C37: =Sheet4!C29 -> 1 | D37: =Sheet4!D29 -> 1 | E37: =Sheet4!E29 -> 1 | F37: =Sheet4!F29 -> 1 | G37: =Sheet4!G29 -> 1 | H37: =Sheet4!H29 -> 1 | I37: =Sheet4!I29 -> 1 | ... AE37: =Sheet4!AE29 -> 1
A38: TEMPLE | B38: =Sheet4!B30 -> 0 | C38: =Sheet4!C30 -> 1 | D38: =Sheet4!D30 -> 1 | E38: =Sheet4!E30 -> 0 | F38: =Sheet4!F30 -> 0 | G38: =Sheet4!G30 -> 0 | H38: =Sheet4!H30 -> 0 | I38: =Sheet4!I30 -> 0 | ... AE38: =Sheet4!AE30 -> 0
A39: WALKING / STEP | B39: =Sheet4!B31 -> 0 | C39: =Sheet4!C31 -> 0 | D39: =Sheet4!D31 -> 0 | E39: =Sheet4!E31 -> 0 | F39: =Sheet4!F31 -> 0 | G39: =Sheet4!G31 -> 0 | H39: =Sheet4!H31 -> 1 | I39: =Sheet4!I31 -> 1 | ... AE39: =Sheet4!AE31 -> 1
A40: ONLINE STUDY | B40: =Sheet4!B32 -> 0 | C40: =Sheet4!C32 -> 0 | D40: =Sheet4!D32 -> 0 | E40: =Sheet4!E32 -> 0 | F40: =Sheet4!F32 -> 0 | G40: =Sheet4!G32 -> 0 | H40: =Sheet4!H32 -> 1 | I40: =Sheet4!I32 -> 0 | ... AE40: =Sheet4!AE32 -> 0
B41: =B12 -> 0 | C41: =C12 -> 0 | D41: =D12 -> 0 | E41: =E12 -> 0 | F41: =F12 -> 0 | G41: =G12 -> 0 | H41: =H12 -> 0 | I41: =I12 -> 0 | J41: =J12 -> 0
B42: DAY 13
B43: DAY 14
B44: DAY 15
B45: DAY 16
B46: DAY 17
B47: DAY 18
B48: DAY 19
B49: DAY 20
B50: DAY 21
B51: DAY 22
B52: DAY 23
B53: DAY 24
... B59: DAY 30

Sheet Sheet1
AF1: Total | AG1: PROGRESS % | BP1: HABBIT TRACKER
AF2: =COUNTIF(Sheet4!B23:AE23,1) -> 8 | AG2: =AF2/30 -> 0.26666667
AF3: =COUNTIF(Sheet4!B24:AE24,1) -> 0 | AG3: =AF3/30 -> 0
AF4: =COUNTIF(Sheet4!B25:AE25,1) -> 3 | AG4: =AF4/30 -> 0.1
AF5: =COUNTIF(Sheet4!B26:AE26,1) -> 4 | AG5: =AF5/30 -> 0.13333333
AF6: =COUNTIF(Sheet4!B27:AE27,1) -> 1 | AG6: =AF6/30 -> 0.033333333
AF7: =COUNTIF(Sheet4!B28:AE28,1) -> 11 | AG7: =AF7/30 -> 0.36666667
AF8: =COUNTIF(Sheet4!B29:AE29,1) -> 14 | AG8: =AF8/30 -> 0.46666667
AF9: =COUNTIF(Sheet4!B30:AE30,1) -> 8 | AG9: =AF9/30 -> 0.26666667
AF10: =COUNTIF(Sheet4!B31:AE31,1) -> 20 | AG10: =AF10/30 -> 0.66666667
AF11: =COUNTIF(Sheet4!B32:AE32,1) -> 6 | AG11: =AF11/30 -> 0.2
AG12: OVERALL PROGRESS
AG13: =AVERAGE(AG2:AG11) -> 0.25
AH14: DAY | AI14: COMPLETE
AH15: DAY 1 | AI15: =COUNTIF(Sheet4!B23:B32,1) -> 1 | AJ15: A | AK15: B
AH16: DAY 2 | AI16: =COUNTIF(Sheet4!C23:C32,1) -> 3 | AJ16: complete | AK16: 37
AH17: DAY 3 | AI17: =COUNTIF(Sheet4!D23:D32,1) -> 3 | AJ17: remaining | AK17: 63
AH18: DAY 4 | AI18: =COUNTIF(Sheet4!E23:E32,1) -> 2
AH19: DAY 5 | AI19: =COUNTIF(Sheet4!F23:F32,1) -> 2
AH20: DAY 6 | AI20: =COUNTIF(Sheet4!G23:G32,1) -> 3
AH21: DAY 7 | AI21: =COUNTIF(Sheet4!H23:H32,1) -> 5
AH22: DAY 8 | AI22: =COUNTIF(Sheet4!I23:I32,1) -> 3
AH23: DAY 9 | AI23: =COUNTIF(Sheet4!J23:J32,1) -> 4
AH24: DAY 10 | AI24: =COUNTIF(Sheet4!K23:K32,1) -> 4
AH25: DAY 11 | AI25: =COUNTIF(Sheet4!L23:L32,1) -> 4
AH26: DAY 12 | AI26: =COUNTIF(Sheet4!M23:M32,1) -> 4
AH27: DAY 13 | AI27: =COUNTIF(Sheet4!N23:N32,1) -> 4
AH28: DAY 14 | AI28: =COUNTIF(Sheet4!O23:O32,1) -> 3
AH29: DAY 15 | AI29: =COUNTIF(Sheet4!P23:P32,1) -> 3
AH30: DAY 16 | AI30: =COUNTIF(Sheet4!Q23:Q32,1) -> 3
AH31: DAY 17 | AI31: =COUNTIF(Sheet4!R23:R32,1) -> 1
AH32: DAY 18 | AI32: =COUNTIF(Sheet4!S23:S32,1) -> 2
AH33: DAY 19 | AI33: =COUNTIF(Sheet4!T23:T32,1) -> 1
AH34: DAY 20 | AI34: =COUNTIF(Sheet4!U23:U32,1) -> 2
AH35: DAY 21 | AI35: =COUNTIF(Sheet4!V23:V32,1) -> 1
AH36: DAY 22 | AI36: =COUNTIF(Sheet4!W23:W32,1) -> 1
AH37: DAY 23 | AI37: =COUNTIF(Sheet4!X23:X32,1) -> 2
AH38: DAY 24 | AI38: =COUNTIF(Sheet4!Y23:Y32,1) -> 1
AH39: DAY 25 | AI39: =COUNTIF(Sheet4!Z23:Z32,1) -> 0
AH40: DAY 26 | AI40: =COUNTIF(Sheet4!AA23:AA32,1) -> 1
...

Sheet Sheet2

Sheet Sheet3
A1: HABBIT TRACKER
N2: =Sheet1!AG13 -> 0.25

Sheet final project
M16: 30 DAYS HABIT TRACKER | N16: Day 1 | O16: Day 2 | P16: Day 3 | Q16: Day 4 | R16: Day 5 | S16: Day 6 | T16: Day 7 | U16: Day 8 | V16: Day 9 | W16: Day 10 | X16: Day 11 | Y16: Day 12 | Z16: Day 13 | AA16: Day 14 | AB16: Day 15 | AC16: Day 16 | AD16: Day 17 | AE16: Day 18 | AF16: Day 19 | AG16: Day 20 | AH16: Day 21 | AI16: Day 22 | AJ16: Day 23 | AK16: Day 24 | AL16: Day 25 | AM16: Day 26 | AN16: Day 27 | AO16: Day 28 | AP16: Day 29 | AQ16: Day 30
M17: WAKE UP AT 5 :30 ⏰ | N17: 1 | O17: 1 | P17: 1 | Q17: 1 | R17: 1 | S17: 1 | T17: 1 | U17: 1 | V17: 1 | W17: 1 | X17: 1 | Y17: 0 | Z17: 1 | AA17: 1 | AB17: 1 | AC17: 1 | AD17: 1 | AE17: 1 | AF17: 1 | AG17: 1 | AH17: 1 | AI17: 1 | AJ17: 1 | AK17: 1 | AL17: 1 | AM17: 1 | AN17: 1 | AO17: 1 | AP17: 1 | AQ17: 1
M18: GYM | N18: 0 | O18: 0 | P18: 0 | Q18: 0 | R18: 0 | S18: 0 | T18: 0 | U18: 0 | V18: 0 | W18: 0 | X18: 0 | Y18: 0 | Z18: 0 | AA18: 0 | AB18: 0 | AC18: 0 | AD18: 0 | AE18: 0 | AF18: 0 | AG18: 0 | AH18: 0 | AI18: 0 | AJ18: 0 | AK18: 0 | AL18: 0 | AM18: 0 | AN18: 0 | AO18: 0 | AP18: 0 | AQ18: 0
M19: Reading /Learning | N19: 1 | O19: 1 | P19: 1 | Q19: 1 | R19: 1 | S19: 1 | T19: 1 | V19: 1 | W19: 1 | X19: 0 | Y19: 1 | Z19: 1 | AA19: 1 | AB19: 1 | AC19: 1 | AD19: 1 | AE19: 1 | AF19: 1 | AG19: 1 | AH19: 1 | AI19: 1 | AJ19: 1 | AK19: 1 | AL19: 1 | AM19: 0 | AP19: 0
M20: Noo Gooning | N20: 1 | O20: 1 | P20: 0 | Q20: 1 | R20: =S23 -> 1 | S20: 1 | T20: 1 | U20: 0 | V20: 0 | W20: 0 | X20: 0 | Y20: 0 | Z20: 0 | AA20: 1 | AB20: 1 | AC20: 1 | AD20: 1 | AE20: 1 | AF20: 1 | AG20: 0 | AH20: 0 | AI20: 0 | AJ20: 0 | AK20: 0 | AL20: 0 | AM20: 0 | AN20: 0 | AP20: 0 | AQ20: 1
M21: Cold Shower | N21: 1 | O21: 0 | P21: 0 | Q21: 0 | R21: 0 | S21: 0 | T21: 0 | U21: 0 | V21: 0 | W21: 0 | X21: 1 | Y21: 1 | Z21: 1 | AA21: 1 | AB21: 1 | AC21: 1 | AD21: 1 | AE21: 1 | AF21: 1 | AG21: 1 | AH21: 1 | AI21: 1 | AJ21: 1 | AK21: 1 | AL21: 1 | AM21: 1 | AN21: 1 | AO21: 1 | AP21: 0
M22: Leaning skill | N22: 1 | O22: 0 | P22: 0 | Q22: 0 | R22: 0 | S22: 1 | T22: 1 | U22: 1 | V22: 1 | W22: 1 | X22: 1 | Y22: 0 | Z22: 1 | AA22: 0 | AB22: 1 | AC22: 1 | AD22: 0 | AE22: 0 | AF22: 0 | AG22: 0 | AH22: 0 | AI22: 0 | AJ22: 0 | AK22: 0 | AL22: 0 | AM22: 0 | AN22: 0 | AP22: 0 | AQ22: 1
M23: Coding | N23: 1 | O23: 1 | P23: 1 | Q23: 1 | R23: 1 | S23: 1 | T23: 1 | U23: 1 | V23: 1 | W23: 1 | X23: 1 | Y23: 1 | Z23: 1 | AA23: 1 | AB23: 1 | AC23: 1 | AD23: 1 | AE23: 1 | AF23: 1 | AG23: 1 | AH23: 1 | AI23: 1 | AJ23: 1 | AK23: 1 | AL23: 1 | AM23: 1 | AN23: 1 | AO23: 1 | AP23: 0 | AQ23: 1
M24: Temple | N24: 1 | O24: 1 | P24: 1 | Q24: =Sheet1!R42 -> 0 | R24: 0 | S24: 0 | T24: 0 | U24: 0 | V24: 0 | W24: 0 | X24: 0 | Y24: 1 | Z24: 1 | AA24: 1 | AB24: 1 | AC24: 1 | AF24: 0 | AG24: 0 | AH24: 0 | AI24: 0 | AJ24: 0 | AK24: 0 | AL24: 0 | AM24: 0 | AN24: 0 | AO24: 0 | AP24: 0
M25: Walking /Step | N25: 1 | O25: 0 | P25: 0 | Q25: 0 | R25: 0 | S25: 0 | T25: 1 | U25: 1 | V25: 1 | W25: 1 | X25: 1 | Y25: 1 | Z25: 1 | AA25: 1 | AB25: 1 | AC25: 1 | AD25: 1 | AF25: 0 | AG25: 0 | AH25: 1 | AI25: 1 | AJ25: 1 | AK25: 1 | AM25: 1 | AN25: 1 | AO25: 1 | AP25: 0 | AQ25: 1
M26: Online Study | N26: 1 | T26: 1 | V26: 1 | W26: 1 | X26: 1 | Y26: 1 | Z26: 1 | AA26: 0 | AB26: 0 | AC26: 1 | AD26: 0 | AE26: 0 | AF26: 0 | AG26: 0 | AH26: 0 | AI26: 0 | AJ26: 0 | AK26: 0 | AL26: 0 | AM26: 0 | AN26: 0 | AO26: 0 | AP26: 0

Sheet Sheet4
A22: 30 DAYS HABIT TRACKER | B22: Day 1 | C22: Day 2 | D22: Day 3 | E22: Day 4 | F22: Day 5 | G22: Day 6 | H22: Day 7 | I22: Day 8 | J22: Day 9 | K22: Day 10 | L22: Day 11 | M22: Day 12 | N22: Day 13 | O22: Day 14 | P22: Day 15 | Q22: Day 16 | R22: Day 17 | S22: Day 18 | T22: Day 19 | U22: Day 20 | V22: Day 21 | W22: Day 22 | X22: Day 23 | Y22: Day 24 | Z22: Day 25 | AA22: Day 26 | AB22: Day 27 | AC22: Day 28 | AD22: Day 29 | AE22: Day 30
A23: WAKE UP AT 5 :30 ⏰ | B23: 1 | C23: 1 | D23: 1 | E23: 1 | F23: 1 | G23: 1 | H23: 1 | I23: 0 | J23: 0 | K23: 0 | L23: 0 | M23: 0 | N23: 0 | O23: 0 | P23: 0 | Q23: 0 | R23: 0 | S23: 0 | T23: 0 | U23: 0 | V23: 0 | W23: 0 | X23: 1 | Y23: 0 | Z23: 0 | AA23: 0 | AB23: 0
A24: GYM | AB24: 0
A25: Reading /Learning | S25: 1 | U25: 1 | AB25: 0 | AD25: 1
A26: Noo Gooning | S26: 1 | T26: 1 | U26: 1 | AB26: 0 | AD26: 1
A27: Cold Shower | AD27: 1
A28: Leaning skill | C28: 0 | D28: 0 | E28: 0 | F28: 0 | G28: 1 | H28: 1 | I28: 1 | J28: 1 | K28: 1 | L28: 1 | M28: 0 | N28: 1 | O28: 0 | P28: 1 | Q28: 1 | R28: 0 | S28: 0 | T28: 0 | U28: 0 | V28: 0 | W28: 0 | X28: 0 | Y28: 0 | Z28: 0 | AA28: 0 | AB28: 0 | AD28: 1 | AE28: 1
A29: Coding | C29: 1 | D29: 1 | E29: 1 | F29: 1 | G29: 1 | H29: 1 | I29: 1 | J29: 1 | K29: 1 | L29: 1 | M29: 1 | N29: 0 | O29: 1 | P29: 0 | Q29: 0 | R29: 0 | S29: 0 | T29: 0 | U29: 0 | V29: 0 | W29: 0 | X29: 0 | Y29: 0 | Z29: 0 | AA29: 0 | AB29: 0 | AC29: 0 | AD29: 1 | AE29: 1
A30: Temple | C30: 1 | D30: 1 | E30: =Sheet1!F53 -> 0 | F30: 0 | G30: 0 | H30: 0 | I30: 0 | J30: 0 | K30: 0 | L30: 0 | M30: 1 | N30: 1 | O30: 1 | P30: 1 | Q30: 1 | T30: 0 | U30: 0 | V30: 0 | W30: 0 | X30: 0 | Y30: 0 | Z30: 0 | AA30: 0 | AB30: 0 | AC30: 0 | AD30: 1
A31: Walking /Step | C31: 0 | D31: 0 | E31: 0 | F31: 0 | G31: 0 | H31: 1 | I31: 1 | J31: 1 | K31: 1 | L31: 1 | M31: 1 | N31: 1 | O31: 1 | P31: 1 | Q31: 1 | R31: 1 | T31: 0 | U31: 0 | V31: 1 | W31: 1 | X31: 1 | Y31: 1 | AA31: 1 | AB31: 1 | AC31: 1 | AD31: 1 | AE31: 1
A32: Online Study | H32: 1 | J32: 1 | K32: 1 | L32: 1 | M32: 1 | N32: 1 | O32: 0 | P32: 0 | Q32: 0 | R32: 0 | S32: 0 | T32: 0 | U32: 0 | V32: 0 | W32: 0 | X32: 0 | Y32: 0 | Z32: 0 | AA32: 0 | AB32: 0 | AC32: 0 | AD32: 0
